<?xml version="1.0" encoding="utf-8"?>
<!-- This URDF was automatically created by SolidWorks to URDF Exporter! Originally created by Stephen Brawner (brawner@gmail.com) 
     Commit Version: 1.5.1-0-g916b5db  Build Version: 1.5.7152.31018
     For more information, please see http://wiki.ros.org/sw_urdf_exporter -->
<robot
  name="smr100e2_description">
  <link
    name="base_link">
    <inertial>
      <origin
        xyz="-0.046026 -0.00048477 0.26269"
        rpy="0 0 0" />
      <mass
        value="31.222" />
      <inertia
        ixx="1.0343"
        ixy="-0.023468"
        ixz="0.035244"
        iyy="2.3307"
        iyz="-0.0070175"
        izz="2.483" />
    </inertial>
    <visual>
      <origin
        xyz="0 0 0"
        rpy="0 0 0" />
      <geometry>
        <mesh
          filename="package://smr100e2_description/meshes/base_link.STL" />
      </geometry>
      <material
        name="">
        <color
          rgba="0.89804 0.91765 0.92941 1" />
      </material>
    </visual>
    <collision>
      <origin
        xyz="0 0 0"
        rpy="0 0 0" />
      <geometry>
        <mesh
          filename="package://smr100e2_description/meshes/base_link.STL" />
      </geometry>
    </collision>
  </link>
  <link
    name="wheel_left_link">
    <inertial>
      <origin
        xyz="5.7206E-08 3.3262E-05 -9.2679E-05"
        rpy="0 0 0" />
      <mass
        value="4.9554" />
      <inertia
        ixx="0.0087272"
        ixy="-4.3288E-09"
        ixz="-2.7053E-08"
        iyy="0.01571"
        iyz="2.8551E-06"
        izz="0.0087185" />
    </inertial>
    <visual>
      <origin
        xyz="0 0 0"
        rpy="0 0 0" />
      <geometry>
        <mesh
          filename="package://smr100e2_description/meshes/wheel_left_link.STL" />
      </geometry>
      <material
        name="">
        <color
          rgba="0.79216 0.79216 0.79216 1" />
      </material>
    </visual>
    <collision>
      <origin
        xyz="0 0 0"
        rpy="0 0 0" />
      <geometry>
        <mesh
          filename="package://smr100e2_description/meshes/wheel_left_link.STL" />
      </geometry>
    </collision>
  </link>
  <joint
    name="wheel_left_joint"
    type="continuous">
    <origin
      xyz="0 0.184 0.075"
      rpy="0 0 0" />
    <parent
      link="base_link" />
    <child
      link="wheel_left_link" />
    <axis
      xyz="0 -1 0" />
    <limit
      effort="0"
      velocity="21" />
  </joint>
  <link
    name="caster_front_left_arm_link">
    <inertial>
      <origin
        xyz="-0.0083559 6.8467E-05 -0.021877"
        rpy="0 0 0" />
      <mass
        value="0.11891" />
      <inertia
        ixx="0.00011866"
        ixy="2.5986E-07"
        ixz="-3.3182E-05"
        iyy="0.00013039"
        iyz="3.8798E-07"
        izz="0.00013729" />
    </inertial>
    <visual>
      <origin
        xyz="0 0 0"
        rpy="0 0 0" />
      <geometry>
        <mesh
          filename="package://smr100e2_description/meshes/caster_front_left_arm_link.STL" />
      </geometry>
      <material
        name="">
        <color
          rgba="0.79216 0.81961 0.93333 1" />
      </material>
    </visual>
    <collision>
      <origin
        xyz="0 0 0"
        rpy="0 0 0" />
      <geometry>
        <mesh
          filename="package://smr100e2_description/meshes/caster_front_left_arm_link.STL" />
      </geometry>
    </collision>
  </link>
  <joint
    name="caster_front_left_arm_joint"
    type="continuous">
    <origin
      xyz="0.3725 0.155 0.11"
      rpy="0 0 0" />
    <parent
      link="base_link" />
    <child
      link="caster_front_left_arm_link" />
    <axis
      xyz="0 0 1" />
  </joint>
  <link
    name="caster_front_left_wheel_link">
    <inertial>
      <origin
        xyz="3.41579619150684E-05 1.00246685701133E-05 9.06356100988104E-06"
        rpy="0 0 0" />
      <mass
        value="0.10622773912148" />
      <inertia
        ixx="5.31582091921393E-05"
        ixy="-1.19552325590283E-08"
        ixz="1.63641579299917E-09"
        iyy="9.07905500875478E-05"
        iyz="-1.30943250319338E-08"
        izz="5.31454154966387E-05" />
    </inertial>
    <visual>
      <origin
        xyz="0 0 0"
        rpy="0 0 0" />
      <geometry>
        <mesh
          filename="package://smr100e2_description/meshes/caster_front_left_wheel_link.STL" />
      </geometry>
      <material
        name="">
        <color
          rgba="0.792156862745098 0.819607843137255 0.933333333333333 1" />
      </material>
    </visual>
    <collision>
      <origin
        xyz="0 0 0"
        rpy="0 0 0" />
      <geometry>
        <mesh
          filename="package://smr100e2_description/meshes/caster_front_left_wheel_link.STL" />
      </geometry>
    </collision>
  </link>
  <joint
    name="caster_front_left_wheel_joint"
    type="continuous">
    <origin
      xyz="-0.04 0 -0.07"
      rpy="0 1.5708 0" />
    <parent
      link="caster_front_left_arm_link" />
    <child
      link="caster_front_left_wheel_link" />
    <axis
      xyz="0 -1 0" />
  </joint>
  <link
    name="caster_rear_left_arm_link">
    <inertial>
      <origin
        xyz="-0.008355850944051 6.84673200635755E-05 -0.0218772617133344"
        rpy="0 0 0" />
      <mass
        value="0.11890585691937" />
      <inertia
        ixx="0.000118659392121093"
        ixy="2.59862865197447E-07"
        ixz="-3.31821021003566E-05"
        iyy="0.000130389155469755"
        iyz="3.87981608747489E-07"
        izz="0.000137285155509039" />
    </inertial>
    <visual>
      <origin
        xyz="0 0 0"
        rpy="0 0 0" />
      <geometry>
        <mesh
          filename="package://smr100e2_description/meshes/caster_rear_left_arm_link.STL" />
      </geometry>
      <material
        name="">
        <color
          rgba="0.792156862745098 0.819607843137255 0.933333333333333 1" />
      </material>
    </visual>
    <collision>
      <origin
        xyz="0 0 0"
        rpy="0 0 0" />
      <geometry>
        <mesh
          filename="package://smr100e2_description/meshes/caster_rear_left_arm_link.STL" />
      </geometry>
    </collision>
  </link>
  <joint
    name="caster_rear_left_arm_joint"
    type="continuous">
    <origin
      xyz="-0.3725 0.155 0.11"
      rpy="0 0 0" />
    <parent
      link="base_link" />
    <child
      link="caster_rear_left_arm_link" />
    <axis
      xyz="0 0 1" />
  </joint>
  <link
    name="caster_rear_left_wheel_link">
    <inertial>
      <origin
        xyz="3.41579619150822E-05 1.002466857003E-05 9.0635610097145E-06"
        rpy="0 0 0" />
      <mass
        value="0.106227739121479" />
      <inertia
        ixx="5.31582091921392E-05"
        ixy="-1.19552325590222E-08"
        ixz="1.63641579318855E-09"
        iyy="9.07905500875474E-05"
        iyz="-1.30943250319557E-08"
        izz="5.31454154966383E-05" />
    </inertial>
    <visual>
      <origin
        xyz="0 0 0"
        rpy="0 0 0" />
      <geometry>
        <mesh
          filename="package://smr100e2_description/meshes/caster_rear_left_wheel_link.STL" />
      </geometry>
      <material
        name="">
        <color
          rgba="0.792156862745098 0.819607843137255 0.933333333333333 1" />
      </material>
    </visual>
    <collision>
      <origin
        xyz="0 0 0"
        rpy="0 0 0" />
      <geometry>
        <mesh
          filename="package://smr100e2_description/meshes/caster_rear_left_wheel_link.STL" />
      </geometry>
    </collision>
  </link>
  <joint
    name="caster_rear_left_wheel_joint"
    type="continuous">
    <origin
      xyz="-0.04 0 -0.07"
      rpy="0 1.5708 0" />
    <parent
      link="caster_rear_left_arm_link" />
    <child
      link="caster_rear_left_wheel_link" />
    <axis
      xyz="0 -1 0" />
  </joint>
  <link
    name="wheel_right_link">
    <inertial>
      <origin
        xyz="-5.72059102653878E-08 -3.32621060118998E-05 -9.26789475841489E-05"
        rpy="0 0 0" />
      <mass
        value="4.95544635924953" />
      <inertia
        ixx="0.00872719589168906"
        ixy="-4.32876753760574E-09"
        ixz="2.70527246089118E-08"
        iyy="0.0157098593873957"
        iyz="-2.85508393702386E-06"
        izz="0.00871854767880612" />
    </inertial>
    <visual>
      <origin
        xyz="0 0 0"
        rpy="0 0 0" />
      <geometry>
        <mesh
          filename="package://smr100e2_description/meshes/wheel_right_link.STL" />
      </geometry>
      <material
        name="">
        <color
          rgba="0.792156862745098 0.792156862745098 0.792156862745098 1" />
      </material>
    </visual>
    <collision>
      <origin
        xyz="0 0 0"
        rpy="0 0 0" />
      <geometry>
        <mesh
          filename="package://smr100e2_description/meshes/wheel_right_link.STL" />
      </geometry>
    </collision>
  </link>
  <joint
    name="wheel_right_joint"
    type="continuous">
    <origin
      xyz="0 -0.184 0.075"
      rpy="0 0 0" />
    <parent
      link="base_link" />
    <child
      link="wheel_right_link" />
    <axis
      xyz="0 1 0" />
    <limit
      effort="0"
      velocity="21" />
  </joint>
  <link
    name="caster_front_right_arm_link">
    <inertial>
      <origin
        xyz="-0.00835585094405666 6.84673200636032E-05 -0.0218772617133322"
        rpy="0 0 0" />
      <mass
        value="0.118905856919371" />
      <inertia
        ixx="0.000118659392121077"
        ixy="2.59862865197085E-07"
        ixz="-3.31821021003519E-05"
        iyy="0.000130389155469756"
        iyz="3.87981608747766E-07"
        izz="0.000137285155509056" />
    </inertial>
    <visual>
      <origin
        xyz="0 0 0"
        rpy="0 0 0" />
      <geometry>
        <mesh
          filename="package://smr100e2_description/meshes/caster_front_right_arm_link.STL" />
      </geometry>
      <material
        name="">
        <color
          rgba="0.792156862745098 0.819607843137255 0.933333333333333 1" />
      </material>
    </visual>
    <collision>
      <origin
        xyz="0 0 0"
        rpy="0 0 0" />
      <geometry>
        <mesh
          filename="package://smr100e2_description/meshes/caster_front_right_arm_link.STL" />
      </geometry>
    </collision>
  </link>
  <joint
    name="caster_front_right_arm_joint"
    type="continuous">
    <origin
      xyz="0.3725 -0.155 0.11"
      rpy="0 0 0" />
    <parent
      link="base_link" />
    <child
      link="caster_front_right_arm_link" />
    <axis
      xyz="0 0 1" />
  </joint>
  <link
    name="caster_front_right_wheel_link">
    <inertial>
      <origin
        xyz="3.41579619150337E-05 1.00246685700023E-05 9.0635610097145E-06"
        rpy="0 0 0" />
      <mass
        value="0.106227739121479" />
      <inertia
        ixx="5.31582091921392E-05"
        ixy="-1.19552325589556E-08"
        ixz="1.63641579320449E-09"
        iyy="9.07905500875475E-05"
        iyz="-1.30943250318352E-08"
        izz="5.31454154966384E-05" />
    </inertial>
    <visual>
      <origin
        xyz="0 0 0"
        rpy="0 0 0" />
      <geometry>
        <mesh
          filename="package://smr100e2_description/meshes/caster_front_right_wheel_link.STL" />
      </geometry>
      <material
        name="">
        <color
          rgba="0.792156862745098 0.819607843137255 0.933333333333333 1" />
      </material>
    </visual>
    <collision>
      <origin
        xyz="0 0 0"
        rpy="0 0 0" />
      <geometry>
        <mesh
          filename="package://smr100e2_description/meshes/caster_front_right_wheel_link.STL" />
      </geometry>
    </collision>
  </link>
  <joint
    name="caster_front_right_wheel_joint"
    type="continuous">
    <origin
      xyz="-0.04 0 -0.07"
      rpy="0 1.5708 0" />
    <parent
      link="caster_front_right_arm_link" />
    <child
      link="caster_front_right_wheel_link" />
    <axis
      xyz="0 1 0" />
  </joint>
  <link
    name="caster_rear_right_arm_link">
    <inertial>
      <origin
        xyz="-0.0083558509440565 6.8467320063742E-05 -0.0218772617133322"
        rpy="0 0 0" />
      <mass
        value="0.118905856919369" />
      <inertia
        ixx="0.000118659392121076"
        ixy="2.59862865197262E-07"
        ixz="-3.31821021003519E-05"
        iyy="0.000130389155469755"
        iyz="3.87981608748015E-07"
        izz="0.000137285155509056" />
    </inertial>
    <visual>
      <origin
        xyz="0 0 0"
        rpy="0 0 0" />
      <geometry>
        <mesh
          filename="package://smr100e2_description/meshes/caster_rear_right_arm_link.STL" />
      </geometry>
      <material
        name="">
        <color
          rgba="0.792156862745098 0.819607843137255 0.933333333333333 1" />
      </material>
    </visual>
    <collision>
      <origin
        xyz="0 0 0"
        rpy="0 0 0" />
      <geometry>
        <mesh
          filename="package://smr100e2_description/meshes/caster_rear_right_arm_link.STL" />
      </geometry>
    </collision>
  </link>
  <joint
    name="caster_rear_right_arm_joint"
    type="continuous">
    <origin
      xyz="-0.3725 -0.155 0.11"
      rpy="0 0 0" />
    <parent
      link="base_link" />
    <child
      link="caster_rear_right_arm_link" />
    <axis
      xyz="0 0 1" />
  </joint>
  <link
    name="caster_rear_right_wheel_link">
    <inertial>
      <origin
        xyz="3.41579619150337E-05 1.00246685700578E-05 9.06356100960348E-06"
        rpy="0 0 0" />
      <mass
        value="0.10622773912148" />
      <inertia
        ixx="5.31582091921392E-05"
        ixy="-1.19552325589846E-08"
        ixz="1.63641579317299E-09"
        iyy="9.07905500875477E-05"
        iyz="-1.30943250317913E-08"
        izz="5.31454154966386E-05" />
    </inertial>
    <visual>
      <origin
        xyz="0 0 0"
        rpy="0 0 0" />
      <geometry>
        <mesh
          filename="package://smr100e2_description/meshes/caster_rear_right_wheel_link.STL" />
      </geometry>
      <material
        name="">
        <color
          rgba="0.792156862745098 0.819607843137255 0.933333333333333 1" />
      </material>
    </visual>
    <collision>
      <origin
        xyz="0 0 0"
        rpy="0 0 0" />
      <geometry>
        <mesh
          filename="package://smr100e2_description/meshes/caster_rear_right_wheel_link.STL" />
      </geometry>
    </collision>
  </link>
  <joint
    name="caster_rear_right_wheel_joint"
    type="continuous">
    <origin
      xyz="-0.04 0 -0.07"
      rpy="0 1.5708 0" />
    <parent
      link="caster_rear_right_arm_link" />
    <child
      link="caster_rear_right_wheel_link" />
    <axis
      xyz="0 1 0" />
  </joint>
  <link
    name="lidar_front_right_link">
    <inertial>
      <origin
        xyz="-0.00233498111285663 -1.38297305401132E-06 -0.0129543211216719"
        rpy="0 0 0" />
      <mass
        value="0.096744416647924" />
      <inertia
        ixx="6.75053726522406E-05"
        ixy="-4.85105087585742E-08"
        ixz="-2.38171293229343E-06"
        iyy="8.2230289282585E-05"
        iyz="-1.88559800565705E-08"
        izz="0.000116331697118463" />
    </inertial>
    <visual>
      <origin
        xyz="0 0 0"
        rpy="0 0 0" />
      <geometry>
        <mesh
          filename="package://smr100e2_description/meshes/lidar_front_right_link.STL" />
      </geometry>
      <material
        name="">
        <color
          rgba="0.898039215686275 0.917647058823529 0.929411764705882 1" />
      </material>
    </visual>
    <collision>
      <origin
        xyz="0 0 0"
        rpy="0 0 0" />
      <geometry>
        <mesh
          filename="package://smr100e2_description/meshes/lidar_front_right_link.STL" />
      </geometry>
    </collision>
  </link>
  <joint
    name="lidar_front_right_joint"
    type="fixed">
    <origin
      xyz="0.4425 0 0.15335"
      rpy="0 0 0" />
    <parent
      link="base_link" />
    <child
      link="lidar_front_right_link" />
    <axis
      xyz="0 0 0" />
  </joint>
  <link
    name="lidar_rear_left_link">
    <inertial>
      <origin
        xyz="-0.00233498111285729 -1.38297305494147E-06 -0.0129543211216724"
        rpy="0 0 0" />
      <mass
        value="0.0967444166479226" />
      <inertia
        ixx="6.75053726522404E-05"
        ixy="-4.85105087574827E-08"
        ixz="-2.38171293229237E-06"
        iyy="8.22302892825826E-05"
        iyz="-1.88559800556491E-08"
        izz="0.000116331697118462" />
    </inertial>
    <visual>
      <origin
        xyz="0 0 0"
        rpy="0 0 0" />
      <geometry>
        <mesh
          filename="package://smr100e2_description/meshes/lidar_rear_left_link.STL" />
      </geometry>
      <material
        name="">
        <color
          rgba="0.898039215686275 0.917647058823529 0.929411764705882 1" />
      </material>
    </visual>
    <collision>
      <origin
        xyz="0 0 0"
        rpy="0 0 0" />
      <geometry>
        <mesh
          filename="package://smr100e2_description/meshes/lidar_rear_left_link.STL" />
      </geometry>
    </collision>
  </link>
  <joint
    name="lidar_rear_left_joint"
    type="fixed">
    <origin
      xyz="-0.4425 0 0.15335"
      rpy="0 0 3.1416" />
    <parent
      link="base_link" />
    <child
      link="lidar_rear_left_link" />
    <axis
      xyz="0 0 0" />
  </joint>
  <link
    name="imu_link">
    <inertial>
      <origin
        xyz="-6.9350586529713E-05 2.10656642644566E-05 -0.00172272577964405"
        rpy="0 0 0" />
      <mass
        value="0.000911356888660493" />
      <inertia
        ixx="2.8541034821061E-08"
        ixy="-2.22197427857319E-10"
        ixz="7.87903579180546E-11"
        iyy="4.99346433608488E-08"
        iyz="-4.13194761847017E-11"
        izz="7.78569805080495E-08" />
    </inertial>
    <visual>
      <origin
        xyz="0 0 0"
        rpy="0 0 0" />
      <geometry>
        <mesh
          filename="package://smr100e2_description/meshes/imu_link.STL" />
      </geometry>
      <material
        name="">
        <color
          rgba="0.792156862745098 0.819607843137255 0.933333333333333 1" />
      </material>
    </visual>
    <collision>
      <origin
        xyz="0 0 0"
        rpy="0 0 0" />
      <geometry>
        <mesh
          filename="package://smr100e2_description/meshes/imu_link.STL" />
      </geometry>
    </collision>
  </link>
  <joint
    name="imu_joint"
    type="fixed">
    <origin
      xyz="0.061 0.0025 0.2591"
      rpy="0 0 -1.5708" />
    <parent
      link="base_link" />
    <child
      link="imu_link" />
    <axis
      xyz="0 0 0" />
  </joint>
  <link
    name="ultrasonic_front_right_side_link">
    <inertial>
      <origin
        xyz="-0.0140934459768421 0.000342739553301497 -0.000343035134600544"
        rpy="0 0 0" />
      <mass
        value="0.00862358242165751" />
      <inertia
        ixx="1.88412480130025E-06"
        ixy="1.71411632756251E-08"
        ixz="-1.98565508058437E-08"
        iyy="6.52390756644082E-07"
        iyz="-2.04292873861296E-08"
        izz="2.00499062028754E-06" />
    </inertial>
    <visual>
      <origin
        xyz="0 0 0"
        rpy="0 0 0" />
      <geometry>
        <mesh
          filename="package://smr100e2_description/meshes/ultrasonic_front_right_side_link.STL" />
      </geometry>
      <material
        name="">
        <color
          rgba="0.792156862745098 0.819607843137255 0.933333333333333 1" />
      </material>
    </visual>
    <collision>
      <origin
        xyz="0 0 0"
        rpy="0 0 0" />
      <geometry>
        <mesh
          filename="package://smr100e2_description/meshes/ultrasonic_front_right_side_link.STL" />
      </geometry>
    </collision>
  </link>
  <joint
    name="ultrasonic_front_right_side_joint"
    type="fixed">
    <origin
      xyz="0.2522 -0.2517 0.3115"
      rpy="0 0 -1.5708" />
    <parent
      link="base_link" />
    <child
      link="ultrasonic_front_right_side_link" />
    <axis
      xyz="0 0 0" />
  </joint>
  <link
    name="ultrasonic_rear_right_side_link">
    <inertial>
      <origin
        xyz="-0.014093445976842 0.000342739553301497 -0.0003430351346006"
        rpy="0 0 0" />
      <mass
        value="0.0086235824216575" />
      <inertia
        ixx="1.88412480130025E-06"
        ixy="1.71411632756239E-08"
        ixz="-1.98565508058438E-08"
        iyy="6.52390756644079E-07"
        iyz="-2.04292873861312E-08"
        izz="2.00499062028754E-06" />
    </inertial>
    <visual>
      <origin
        xyz="0 0 0"
        rpy="0 0 0" />
      <geometry>
        <mesh
          filename="package://smr100e2_description/meshes/ultrasonic_rear_right_side_link.STL" />
      </geometry>
      <material
        name="">
        <color
          rgba="0.792156862745098 0.819607843137255 0.933333333333333 1" />
      </material>
    </visual>
    <collision>
      <origin
        xyz="0 0 0"
        rpy="0 0 0" />
      <geometry>
        <mesh
          filename="package://smr100e2_description/meshes/ultrasonic_rear_right_side_link.STL" />
      </geometry>
    </collision>
  </link>
  <joint
    name="ultrasonic_rear_right_side_joint"
    type="fixed">
    <origin
      xyz="-0.2878 -0.2517 0.3115"
      rpy="0 0 -1.5708" />
    <parent
      link="base_link" />
    <child
      link="ultrasonic_rear_right_side_link" />
    <axis
      xyz="0 0 0" />
  </joint>
  <link
    name="ultrasonic_rear_right_link">
    <inertial>
      <origin
        xyz="-0.0140934459768421 0.000342739553301497 -0.000343035134600655"
        rpy="0 0 0" />
      <mass
        value="0.00862358242165749" />
      <inertia
        ixx="1.88412480130025E-06"
        ixy="1.71411632756204E-08"
        ixz="-1.98565508058432E-08"
        iyy="6.5239075664408E-07"
        iyz="-2.04292873861313E-08"
        izz="2.00499062028753E-06" />
    </inertial>
    <visual>
      <origin
        xyz="0 0 0"
        rpy="0 0 0" />
      <geometry>
        <mesh
          filename="package://smr100e2_description/meshes/ultrasonic_rear_right_link.STL" />
      </geometry>
      <material
        name="">
        <color
          rgba="0.792156862745098 0.819607843137255 0.933333333333333 1" />
      </material>
    </visual>
    <collision>
      <origin
        xyz="0 0 0"
        rpy="0 0 0" />
      <geometry>
        <mesh
          filename="package://smr100e2_description/meshes/ultrasonic_rear_right_link.STL" />
      </geometry>
    </collision>
  </link>
  <joint
    name="ultrasonic_rear_right_joint"
    type="fixed">
    <origin
      xyz="-0.4902 -0.1487 0.3265"
      rpy="0 0 3.1416" />
    <parent
      link="base_link" />
    <child
      link="ultrasonic_rear_right_link" />
    <axis
      xyz="0 0 0" />
  </joint>
  <link
    name="ultrasonic_rear_left_link">
    <inertial>
      <origin
        xyz="-0.014093445976842 0.000342739553301497 -0.000343035134600711"
        rpy="0 0 0" />
      <mass
        value="0.00862358242165748" />
      <inertia
        ixx="1.88412480130025E-06"
        ixy="1.71411632756221E-08"
        ixz="-1.98565508058438E-08"
        iyy="6.52390756644077E-07"
        iyz="-2.0429287386132E-08"
        izz="2.00499062028753E-06" />
    </inertial>
    <visual>
      <origin
        xyz="0 0 0"
        rpy="0 0 0" />
      <geometry>
        <mesh
          filename="package://smr100e2_description/meshes/ultrasonic_rear_left_link.STL" />
      </geometry>
      <material
        name="">
        <color
          rgba="0.792156862745098 0.819607843137255 0.933333333333333 1" />
      </material>
    </visual>
    <collision>
      <origin
        xyz="0 0 0"
        rpy="0 0 0" />
      <geometry>
        <mesh
          filename="package://smr100e2_description/meshes/ultrasonic_rear_left_link.STL" />
      </geometry>
    </collision>
  </link>
  <joint
    name="ultrasonic_rear_left_joint"
    type="fixed">
    <origin
      xyz="-0.4902 0.1513 0.3265"
      rpy="0 0 3.1416" />
    <parent
      link="base_link" />
    <child
      link="ultrasonic_rear_left_link" />
    <axis
      xyz="0 0 0" />
  </joint>
  <link
    name="ultrasonic_rear_left_side_link">
    <inertial>
      <origin
        xyz="-0.014093445976842 0.000342739553301497 -0.000343035134600544"
        rpy="0 0 0" />
      <mass
        value="0.00862358242165751" />
      <inertia
        ixx="1.88412480130026E-06"
        ixy="1.71411632756226E-08"
        ixz="-1.98565508058443E-08"
        iyy="6.52390756644085E-07"
        iyz="-2.04292873861324E-08"
        izz="2.00499062028755E-06" />
    </inertial>
    <visual>
      <origin
        xyz="0 0 0"
        rpy="0 0 0" />
      <geometry>
        <mesh
          filename="package://smr100e2_description/meshes/ultrasonic_rear_left_side_link.STL" />
      </geometry>
      <material
        name="">
        <color
          rgba="0.792156862745098 0.819607843137255 0.933333333333333 1" />
      </material>
    </visual>
    <collision>
      <origin
        xyz="0 0 0"
        rpy="0 0 0" />
      <geometry>
        <mesh
          filename="package://smr100e2_description/meshes/ultrasonic_rear_left_side_link.STL" />
      </geometry>
    </collision>
  </link>
  <joint
    name="ultrasonic_rear_left_side_link"
    type="fixed">
    <origin
      xyz="-0.2872 0.2537 0.3115"
      rpy="0 0 1.5708" />
    <parent
      link="base_link" />
    <child
      link="ultrasonic_rear_left_side_link" />
    <axis
      xyz="0 0 0" />
  </joint>
  <link
    name="ultrasonic_front_left_side_link">
    <inertial>
      <origin
        xyz="-0.014093445976842 0.000342739553301497 -0.000343035134600544"
        rpy="0 0 0" />
      <mass
        value="0.00862358242165751" />
      <inertia
        ixx="1.88412480130025E-06"
        ixy="1.71411632756236E-08"
        ixz="-1.9856550805845E-08"
        iyy="6.52390756644085E-07"
        iyz="-2.04292873861329E-08"
        izz="2.00499062028754E-06" />
    </inertial>
    <visual>
      <origin
        xyz="0 0 0"
        rpy="0 0 0" />
      <geometry>
        <mesh
          filename="package://smr100e2_description/meshes/ultrasonic_front_left_side_link.STL" />
      </geometry>
      <material
        name="">
        <color
          rgba="0.792156862745098 0.819607843137255 0.933333333333333 1" />
      </material>
    </visual>
    <collision>
      <origin
        xyz="0 0 0"
        rpy="0 0 0" />
      <geometry>
        <mesh
          filename="package://smr100e2_description/meshes/ultrasonic_front_left_side_link.STL" />
      </geometry>
    </collision>
  </link>
  <joint
    name="ultrasonic_front_left_side_joint"
    type="fixed">
    <origin
      xyz="0.2528 0.2537 0.3115"
      rpy="0 0 1.5708" />
    <parent
      link="base_link" />
    <child
      link="ultrasonic_front_left_side_link" />
    <axis
      xyz="0 0 0" />
  </joint>
  <link
    name="ultrasonic_front_left_link">
    <inertial>
      <origin
        xyz="-0.014093445976842 0.000342739553301497 -0.000343035134600711"
        rpy="0 0 0" />
      <mass
        value="0.00862358242165747" />
      <inertia
        ixx="1.88412480130024E-06"
        ixy="1.71411632756236E-08"
        ixz="-1.98565508058437E-08"
        iyy="6.52390756644079E-07"
        iyz="-2.04292873861308E-08"
        izz="2.00499062028753E-06" />
    </inertial>
    <visual>
      <origin
        xyz="0 0 0"
        rpy="0 0 0" />
      <geometry>
        <mesh
          filename="package://smr100e2_description/meshes/ultrasonic_front_left_link.STL" />
      </geometry>
      <material
        name="">
        <color
          rgba="0.792156862745098 0.819607843137255 0.933333333333333 1" />
      </material>
    </visual>
    <collision>
      <origin
        xyz="0 0 0"
        rpy="0 0 0" />
      <geometry>
        <mesh
          filename="package://smr100e2_description/meshes/ultrasonic_front_left_link.STL" />
      </geometry>
    </collision>
  </link>
  <joint
    name="ultrasonic_front_left_link"
    type="fixed">
    <origin
      xyz="0.4967 0.1507 0.311"
      rpy="0 0 0" />
    <parent
      link="base_link" />
    <child
      link="ultrasonic_front_left_link" />
    <axis
      xyz="0 0 0" />
  </joint>
  <link
    name="ultrasonic_front_right_link">
    <inertial>
      <origin
        xyz="-0.0140934459768419 0.000342739553301497 -0.000343035134600544"
        rpy="0 0 0" />
      <mass
        value="0.00862358242165747" />
      <inertia
        ixx="1.88412480130024E-06"
        ixy="1.71411632756226E-08"
        ixz="-1.9856550805844E-08"
        iyy="6.52390756644078E-07"
        iyz="-2.042928738613E-08"
        izz="2.00499062028753E-06" />
    </inertial>
    <visual>
      <origin
        xyz="0 0 0"
        rpy="0 0 0" />
      <geometry>
        <mesh
          filename="package://smr100e2_description/meshes/ultrasonic_front_right_link.STL" />
      </geometry>
      <material
        name="">
        <color
          rgba="0.792156862745098 0.819607843137255 0.933333333333333 1" />
      </material>
    </visual>
    <collision>
      <origin
        xyz="0 0 0"
        rpy="0 0 0" />
      <geometry>
        <mesh
          filename="package://smr100e2_description/meshes/ultrasonic_front_right_link.STL" />
      </geometry>
    </collision>
  </link>
  <joint
    name="ultrasonic_front_right_right"
    type="fixed">
    <origin
      xyz="0.4967 -0.1493 0.311"
      rpy="0 0 0" />
    <parent
      link="base_link" />
    <child
      link="ultrasonic_front_right_link" />
    <axis
      xyz="0 0 0" />
  </joint>
</robot>